<?xml version='1.0'?>
<robot name="eddierobot">

  <!-- Color Definitions -->
  <material name="gray">
    <color rgba="0.1 0.1 0.2 1" />
  </material>
  <material name="gray_light">
    <color rgba="0.2 0.2 0.2 1" />
  </material>
  <material name="black">
    <color rgba="0 0 0 1" />
  </material>
  <material name="gray_next">
    <color rgba="0.1 0.1 0.1 1" />
  </material>

  <!-- Base Link Disk Bottom - Eddie Chassis -->
  <link name="base_link">
    <visual>
      <origin xyz="0 0 0.1" rpy="0 0 0" />
      <geometry>
        <cylinder length="0.02" radius="0.225" />
      </geometry>
      <material name="gray" />
    </visual>
  </link>

  <!-- Base Link Disk Top -->
  <link name="top_base_link">
    <visual>
      <origin xyz="0 0 0.23" rpy="0 0 0" />
      <geometry>
        <cylinder length="0.02" radius="0.225" />
      </geometry>
      <material name="gray" />
    </visual>
  </link>

  <joint name="tbl_joint" type="fixed">
    <parent link="base_link" />
    <child link="top_base_link" />
    <origin xyz="0 0 0" rpy="0 0 0" />
  </joint>

  <!-- Base Link Structural Link -->
  <link name="connection_link">
    <visual>
      <origin xyz="0 0 0.165" rpy="0 0 0" />
      <geometry>
        <cylinder length="0.14" radius="0.05" />
      </geometry>
      <material name="gray_next" />
    </visual>
  </link>

  <joint name="connection_joint" type="fixed">
    <parent link="base_link" />
    <child link="connection_link" />
    <origin xyz="0 0 0" rpy="0 0 0" />
  </joint>

  <!-- Camera Stand 1 -->
  <link name="stand_1_link">
    <visual>
      <origin xyz="0.2 0.05 0.39" rpy="0 0 0" />
      <geometry>
        <cylinder length="0.3" radius="0.01" />
      </geometry>
      <material name="gray_light" />
    </visual>
  </link>

  <joint name="s1_joint" type="fixed">
    <parent link="base_link" />
    <child link="stand_1_link" />
    <origin xyz="0 0 0" rpy="0 0 0" />
  </joint>

  <!-- Camera Stand 2 -->
  <link name="stand_2_link">
    <visual>
      <origin xyz="0.2 -0.05 0.39" rpy="0 0 0" />
      <geometry>
        <cylinder length="0.3" radius="0.01" />
      </geometry>
      <material name="gray_light" />
    </visual>
  </link>

  <joint name="s2_joint" type="fixed">
    <parent link="base_link" />
    <child link="stand_2_link" />
    <origin xyz="0 0 0" rpy="0 0 0" />
  </joint>

  <!-- Camera Stand Top -->
  <link name="stand_top_link">
    <visual>
      <origin xyz="0.2 0 0.54" rpy="0 0 0" />
      <geometry>
        <box size="0.05 0.15 0.01" />
      </geometry>
      <material name="gray_next" />
    </visual>
  </link>

  <joint name="st_joint" type="fixed">
    <parent link="base_link" />
    <child link="stand_top_link" />
    <origin xyz="0 0 0" rpy="0 0 0" />
  </joint>

  <!-- Right Wheel -->
  <link name="right_wheel">
    <visual>
      <origin xyz="0 0 0" rpy="1.570795 0 0" />
      <geometry>
        <cylinder length="0.02" radius="0.075" />
      </geometry>
      <material name="black" />
    </visual>
  </link>

  <joint name="joint_right_wheel" type="continuous">
    <parent link="base_link" />
    <child link="right_wheel" />
    <origin xyz="0 -0.20 0.085" rpy="0 0 0" />
    <axis xyz="0 1 0" rpy="0 0 0" />
  </joint>

  <!-- Left Wheel -->
  <link name="left_wheel">
    <visual>
      <origin xyz="0 0 0" rpy="1.570795 0 0" />
      <geometry>
        <cylinder length="0.02" radius="0.075" />
      </geometry>
      <material name="black" />
    </visual>
  </link>

  <joint name="joint_left_wheel" type="continuous">
    <parent link="base_link" />
    <child link="left_wheel" />
    <origin xyz="0 0.20 0.085" rpy="0 0 0" />
    <axis xyz="0 1 0" rpy="0 0 0" />
  </joint>

  <!-- Front Wheel -->
  <link name="front_wheel">
    <visual>
      <origin xyz="0 0 0" rpy="1.570795 0 0" />
      <geometry>
        <cylinder length="0.01" radius="0.04" />
      </geometry>
      <material name="black" />
    </visual>
  </link>

  <joint name="joint_front_wheel" type="continuous">
    <parent link="base_link" />
    <child link="front_wheel" />
    <origin xyz="0.20 0 0.05" rpy="0 0 0" />
    <axis xyz="0 1 0" rpy="0 0 0" />
  </joint>

  <!-- Rear Wheel -->
  <link name="rear_wheel">
    <visual>
      <origin xyz="0 0 0" rpy="1.570795 0 0" />
      <geometry>
        <cylinder length="0.01" radius="0.04" />
      </geometry>
      <material name="black" />
    </visual>
  </link>

  <joint name="joint_rear_wheel" type="continuous">
    <parent link="base_link" />
    <child link="rear_wheel" />
    <origin xyz="-0.20 0 0.05" rpy="0 0 0" />
    <axis xyz="0 1 0" rpy="0 0 0" />
  </joint>

</robot>