<?xml version='1.0'?>
<robot name="fourwheelrobot">

  <!-- Color Definitions -->
  <material name="red">
    <color rgba="1.0 0.0 0.0 1" />
  </material>
  <material name="black">
    <color rgba="0.05 0.05 0.05 1" />
  </material>

  <!-- Base link - Robot Chassis -->
  <link name="base_link">
    <visual>
      <origin xyz="0 0 0" rpy="0 0 0" />
      <geometry>
        <!-- Length, Width, Height -->
        <box size="1.1 0.7 0.5" />
      </geometry>
      <material name="red" />
    </visual>
  </link>

  <!-- Front Right Wheel -->
  <link name="f_r_wheel">
    <visual>
      <origin xyz="0 0 0" rpy="1.570795 0 0" />
      <geometry>
        <cylinder length="0.1" radius="0.15" />
      </geometry>
      <material name="black" />
    </visual>
  </link>

  <joint name="joint_f_r_wheel" type="continuous">
    <parent link="base_link" />
    <child link="f_r_wheel" />
    <origin xyz="0.45 -0.35 -0.20" rpy="0 0 0" />
    <axis xyz="0 1 0" rpy="0 0 0" />
  </joint>

  <!-- Front Left Wheel -->
  <link name="f_l_wheel">
    <visual>
      <origin xyz="0 0 0" rpy="1.570795 0 0" />
      <geometry>
        <cylinder length="0.1" radius="0.15" />
      </geometry>
      <material name="black" />
    </visual>
  </link>

  <joint name="joint_f_l_wheel" type="continuous">
    <parent link="base_link" />
    <child link="f_l_wheel" />
    <origin xyz="0.45 0.35 -0.20" rpy="0 0 0" />
    <axis xyz="0 1 0" rpy="0 0 0" />
  </joint>

  <!-- Back Right Wheel -->
  <link name="b_r_wheel">
    <visual>
      <origin xyz="0 0 0" rpy="1.570795 0 0" />
      <geometry>
        <cylinder length="0.05" radius="0.10" />
      </geometry>
      <material name="black" />
    </visual>
  </link>

  <joint name="joint_b_r_wheel" type="continuous">
    <parent link="base_link" />
    <child link="b_r_wheel" />
    <origin xyz="-0.45 -0.35 -0.25" rpy="0 0 0" />
    <axis xyz="0 1 0" rpy="0 0 0" />
  </joint>

  <!-- Back Left Wheel -->
  <link name="b_l_wheel">
    <visual>
      <origin xyz="0 0 0" rpy="1.570795 0 0" />
      <geometry>
        <cylinder length="0.05" radius="0.10" />
      </geometry>
      <material name="black" />
    </visual>
  </link>

  <joint name="joint_b_l_wheel" type="continuous">
    <parent link="base_link" />
    <child link="b_l_wheel" />
    <origin xyz="-0.45 0.35 -0.25" rpy="0 0 0" />
    <axis xyz="0 1 0" rpy="0 0 0" />
  </joint>

</robot>
